# catchBlock

Error handling is a crucial aspect of writing robust JavaScript code. JavaScript provides a try...catch block to handle errors gracefully. The basic idea behind error handling using try...catch is to wrap the potentially problematic code within a try block, and if an error occurs, the code inside the catch block will be executed to handle the error situation.
Thought Process for Error Handling using try...catch:

    Identify Potentially Risky Code: Examine your code and identify parts that may throw errors. These could be operations like accessing non-existent properties, calling undefined functions, or performing mathematical operations that could result in unexpected results.

    Wrap Risky Code in try Block: Enclose the risky code within a try block. If an error occurs within this block, the execution will immediately jump to the corresponding catch block.

    Catch and Handle the Error: In the catch block, you can handle the error in a way that is appropriate for your application. You can log the error, display a user-friendly message, or take any necessary actions to recover from the error gracefully.

    Optional: finally Block: Optionally, you can use a finally block after the catch block. The code in the finally block will always run, regardless of whether an error occurred or not. This is useful for clean-up tasks that need to be performed regardless of the outcome.

Example Implementation:

Let's consider an example where we have a function that performs division between two numbers. We'll handle the potential error of division by zero using the try...catch block.
In this example, the divideNumbers function takes two arguments and performs division between them. However, before performing the division, it checks if the divisor (b) is zero. If it's zero, we throw a new Error object with a custom error message.

If the division is successful (non-zero divisor), the result is returned. If the divisor is zero and an error is thrown, the code jumps to the catch block, where the error is handled by logging an error message and returning a user-friendly message. The finally block, if present, will always execute after the try and catch blocks, regardless of whether an error occurred or not. It is useful for cleanup tasks.

By using try...catch blocks, you can effectively handle errors in your JavaScript code and provide a smoother experience for your users by gracefully recovering from unexpected situations.
